Workbook

Sheet Report
C4: Threat Model Report
C5: 1. General Information
C6: Application Name | F6: MCP
C7: Date | F7: 45919
C8: Status | F8: Ongoing
C9: Description | F9: Evaluate severity and score for threats
C10: Document Owner | F10: William
C11: Participants | F11: NYIT students
C12: Reviewer | F12: Charoes
C13: 2. Feature Document Link
C14: Architecture | F14: https://datatracker.ietf.org/doc/html/rfc7662#page-3
C15: UI Flow | F15: https://www.redhat.com/en/blog/model-context-protocol-mcp-understanding-security-risks-and-controls
C16: 3. Threat Statistics
C17: STRIDE Category | F17: Threat Severity | K17: Threat Status
F18: TOTAL | G18: CRITICAL | H18: HIGH | I18: MEDIUM | J18: LOW | K18: Mitigated | L18: Need Mitigation
C19: Spoofing | F19: =SUM(G19:J19) -> 4 | G19: =COUNTIFS('Threat List'!E3:E100,"Spoofing",'Threat List'!K3:K100,">=40",'Threat List'!K3:K100,"<=50") -> 1 | H19: =COUNTIFS('Threat List'!E3:E100,"Spoofing",'Threat List'!K3:K100,">25",'Threat List'!K3:K100,"<40") -> 2 | I19: =COUNTIFS('Threat List'!E3:E100,"Spoofing",'Threat List'!K3:K100,">=11",'Threat List'!K3:K100,"<25") -> 1 | J19: =COUNTIFS('Threat List'!E3:E100,"Spoofing",'Threat List'!K3:K100,">0",'Threat List'!K3:K100,"<=10") -> 0 | K19: =COUNTIFS('Threat List'!E3:E100,"Spoofing",'Threat List'!M3:M100,"Mitigated") -> 0 | L19: =COUNTIFS('Threat List'!E3:E100,"Spoofing",'Threat List'!M3:M100,"Need Mitigation") -> 2
C20: Tampering | F20: =SUM(G20:J20) -> 9 | G20: =COUNTIFS('Threat List'!E3:E100,"Tampering",'Threat List'!K3:K100,">=40",'Threat List'!K3:K100,"<=50") -> 2 | H20: =COUNTIFS('Threat List'!E3:E100,"Tampering",'Threat List'!K3:K100,">25",'Threat List'!K3:K100,"<40") -> 7 | I20: =COUNTIFS('Threat List'!E3:E100,"Tampering",'Threat List'!K3:K100,">=11",'Threat List'!K3:K100,"<25") -> 0 | J20: =COUNTIFS('Threat List'!E3:E100,"Tampering",'Threat List'!K3:K100,">0",'Threat List'!K3:K100,"<=10") -> 0 | K20: =COUNTIFS('Threat List'!E3:E100,"Tampering",'Threat List'!M3:M100,"Mitigated") -> 0 | L20: =COUNTIFS('Threat List'!E3:E100,"Tampering",'Threat List'!M3:M100,"Need Mitigation") -> 2
C21: Repudiation | F21: =SUM(G21:J21) -> 1 | G21: =COUNTIFS('Threat List'!E3:E100,"Repudiation",'Threat List'!K3:K100,">=40",'Threat List'!K3:K100,"<=50") -> 0 | H21: =COUNTIFS('Threat List'!E3:E100,"Repudiation",'Threat List'!K3:K100,">25",'Threat List'!K3:K100,"<40") -> 0 | I21: =COUNTIFS('Threat List'!E3:E100,"Repudiation",'Threat List'!K3:K100,">=11",'Threat List'!K3:K100,"<25") -> 1 | J21: =COUNTIFS('Threat List'!E3:E100,"Repudiation",'Threat List'!K3:K100,">0",'Threat List'!K3:K100,"<=10") -> 0 | K21: =COUNTIFS('Threat List'!E3:E100,"Repudiation",'Threat List'!M3:M100,"Mitigated") -> 0 | L21: =COUNTIFS('Threat List'!E3:E100,"Repudiation",'Threat List'!M3:M100,"Need Mitigation") -> 0
C22: Information Disclosure | F22: =SUM(G22:J22) -> 9 | G22: =COUNTIFS('Threat List'!E3:E100,"Information Disclosure",'Threat List'!K3:K100,">=40",'Threat List'!K3:K100,"<=50") -> 1 | H22: =COUNTIFS('Threat List'!E3:E100,"Information Disclosure",'Threat List'!K3:K100,">25",'Threat List'!K3:K100,"<40") -> 6 | I22: =COUNTIFS('Threat List'!E3:E100,"Information Disclosure",'Threat List'!K3:K100,">=11",'Threat List'!K3:K100,"<25") -> 2 | J22: =COUNTIFS('Threat List'!E3:E100,"Information Disclosure",'Threat List'!K3:K100,">0",'Threat List'!K3:K100,"<=10") -> 0 | K22: =COUNTIFS('Threat List'!E3:E100,"Information Disclosure",'Threat List'!M3:M100,"Mitigated") -> 0 | L22: =COUNTIFS('Threat List'!E3:E100,"Information Disclosure",'Threat List'!M3:M100,"Need Mitigation") -> 0
C23: Denial of Service (DoS) | F23: =SUM(G23:J23) -> 7 | G23: =COUNTIFS('Threat List'!E3:E100,"Denial of Service (DoS)",'Threat List'!K3:K100,">=40",'Threat List'!K3:K100,"<=50") -> 2 | H23: =COUNTIFS('Threat List'!E3:E100,"Denial of Service (DoS)",'Threat List'!K3:K100,">25",'Threat List'!K3:K100,"<40") -> 4 | I23: =COUNTIFS('Threat List'!E3:E100,"Denial of Service (DoS)",'Threat List'!K3:K100,">=11",'Threat List'!K3:K100,"<25") -> 1 | J23: =COUNTIFS('Threat List'!E3:E100,"Denial of Service (DoS)",'Threat List'!K3:K100,">0",'Threat List'!K3:K100,"<=10") -> 0 | K23: =COUNTIFS('Threat List'!E3:E100,"Denial of Service (DoS)",'Threat List'!M3:M100,"Mitigated") -> 0 | L23: =COUNTIFS('Threat List'!E3:E100,"Denial of Service (DoS)",'Threat List'!M3:M100,"Need Mitigation") -> 3
C24: Elevation Of Privilege | F24: =SUM(G24:J24) -> 3 | G24: =COUNTIFS('Threat List'!E3:E100,"Elevation Of Privilege",'Threat List'!K3:K100,">=40",'Threat List'!K3:K100,"<=50") -> 0 | H24: =COUNTIFS('Threat List'!E3:E100,"Elevation Of Privilege",'Threat List'!K3:K100,">25",'Threat List'!K3:K100,"<40") -> 2 | I24: =COUNTIFS('Threat List'!E3:E100,"Elevation Of Privilege",'Threat List'!K3:K100,">=11",'Threat List'!K3:K100,"<25") -> 1 | J24: =COUNTIFS('Threat List'!E3:E100,"Elevation Of Privilege",'Threat List'!K3:K100,">0",'Threat List'!K3:K100,"<=10") -> 0 | K24: =COUNTIFS('Threat List'!E3:E100,"Elevation Of Privilege",'Threat List'!M3:M100,"Mitigated") -> 0 | L24: =COUNTIFS('Threat List'!E3:E100,"Elevation Of Privilege",'Threat List'!M3:M100,"Need Mitigation") -> 1
C25: Total | F25: =SUM(G25:J25) -> 33 | G25: =SUM(G19:G24) -> 6 | H25: =SUM(H19:H24) -> 21 | I25: =SUM(I19:I24) -> 6 | J25: =SUM(J19:J24) -> 0 | K25: =SUM(K19:K24) -> 0 | L25: =SUM(L19:L24) -> 8

Sheet Assets
B2: Assets?? | C2: Assets are the valuable resources or components that attackers might target, following example contains list of assets related to an inventory management system
B3: Assets Category | C3: Assets List
B4: Physical Assets | C4: Servers/Workstations: Hardware running the inventory management software, databases, and supporting services.
C5: Barcode Scanners: Handheld or fixed devices used to scan products and update inventory.
C6: RFID Devices/Readers: Devices that read RFID tags on inventory items to track movement and stock levels.
C7: Networking Equipment: Routers, switches, firewalls, and access points that handle internal communication between systems.
C8: Printers: For printing receipts, shipping labels, inventory reports, or barcodes.
C9: Backup Storage: Physical storage devices (e.g., external hard drives, tape drives, network-attached storage) used for system backups.
C10: Security Cameras: If used for physical security of the on-premise infrastructure.
B11: Digital Assets | C11: Inventory Data: The actual inventory records, including product details (name, ID, price, quantity, etc.) stored in databases.
C12: Product Catalog: Data related to all the products managed by the system, including descriptions, pricing, categories, etc.
C13: User Credentials: Username and password information for employees, administrators, and external users interacting with the system.
C14: Database: The structured storage where inventory, transactional data, user data, and system logs are stored. This may include: Stock Levels Transaction History (e.g., purchase orders, sales, returns) Supplier/Customer Information Financial Data
C15: Application Code: The source code of the inventory management software that provides functionality for tracking, reporting, and auditing inventory.
C16: Configuration Files: System configurations, application settings, and environmental settings for the inventory management system.
C17: Security Keys/Certificates: Cryptographic keys or certificates used for encryption (e.g., SSL certificates, database encryption keys).
C18: Logs: Detailed system logs, including access logs, audit logs, transaction logs, and error logs.
C19: Backup Data: Copies of critical data (e.g., full or incremental backups of inventory, configuration, or system data).
B20: Logical Assets | C20: Access Control Lists (ACLs): Definitions of user roles and permissions that control access to various system resources.
C21: Authentication System: The mechanism used to verify users, such as single sign-on (SSO) systems, multi-factor authentication (MFA), or traditional user-password schemes
C22: API Endpoints: Interfaces through which other systems or services interact with the inventory management system, possibly exposing inventory data or functionality.
C23: Network Segments: Defined segments of the network that provide isolation for the inventory system from other internal networks or external services.
C24: Workflow Rules: The business rules that define inventory processes, such as restocking, order processing, stock adjustments, and returns.
C25: Change Management System: A system used to track changes to the inventory system, such as software updates, configuration changes, and hardware modifications.
B26: Human Assets | C26: Employees: Staff who use the inventory system for day-to-day operations (e.g., warehouse staff, procurement, sales).
C27: Administrators: Users with elevated privileges who have the ability to configure and maintain the system.
C28: Third-Party Vendors: External parties who might interact with the system for maintenance, development, or integration.
C29: Customers: External users (e.g., via online ordering) who may interact with the system for purchasing or tracking inventory.
B30: Software Assets | C30: Operating System (OS): The platform on which the inventory management software runs (e.g., Windows Server, Linux).
C31: Database Management System (DBMS): The software responsible for storing and managing inventory data, such as SQL Server, Oracle, or MySQL.
C32: Networking Protocols: Communication protocols used for data transmission between devices and servers (e.g., TCP/IP, HTTP/HTTPS, FTP, etc.).
C33: Backup Software: Tools used to automate and manage system and data backups.
C34: Security Tools: Software used to secure the system, including antivirus programs, firewalls, intrusion detection/prevention systems (IDS/IPS), and encryption tools.
C35: Monitoring Software: Tools that continuously monitor the health and performance
B36: External Assets | C36: External APIs: Third-party services or applications that interact with the IMS, such as shipping providers, payment processors, or tax calculation services.
C37: Cloud Storage: If used for offsite backups or archiving, external cloud storage services (e.g., Amazon S3, Azure Blob Storage).
B38: Data Assets | C38: Sensitive Personal Information (PII): Customer or employee personal data (e.g., contact information, billing addresses, payment methods) stored or processed by the system.
C39: Financial Records: Data related to sales, expenses, profit margins, and other financial aspects of the inventory management system.
C40: Audit Data: Records of actions taken within the inventory system, especially for regulatory or compliance reasons.
C41: Intellectual Property: Proprietary data such as trade secrets, system designs, custom algorithms, or business logic embedded in the software
...

Sheet DFD
D2: Data Flow Diagram
D4: Link: | E4: https://owasp.org/www-community/Threat_Modeling_Process

Sheet Threat List
A1: Threat Description | E1: Threat Category | F1: Threat Risk Assessment | L1: Mitigation Details
A2: Threat ID | B2: Interaction / Component | C2: Threat Actor | D2: List the threats and scenario here, broken up by the STRIDE category | E2: STRIDE | F2: Damage: How much of damage will be caused? | G2: Reproducibility: How Easily Can the Attack Be Reproduced? | H2: Exploitability: What’s Required to Launch the Attack? | I2: Affected Users: How Many People Would the Attack Affect? | J2: Discoverability: How Easy Is the Vulnerability to Discover? | K2: Overall Threat Rating: Critical (40–50) High (25–39) Medium (11–24) Low (1–10) | L2: Mitigation Solution: Provide detail of solution to mitigate the threat | M2: Mitigation Status: provide detail status of mitigtion | N2: Mitigaton Owner: Provide detail where the mitigation will be added with owner e.g: infra:security | O2: Other Remarks
A3: 1 | C3: Impersonation | D3: Attackers pretend to be valid clients to access the system without authorization. | E3: Spoofing | F3: 5: Information disclosure | G3: 5: Complex | H3: 2.5: Advanced programming and networking skills | I3: 10: All users | J3: 5: HTTP requests can uncover the vulnerability | K3: =IF(OR(ISBLANK(F3),ISBLANK(G3),ISBLANK(H3),ISBLANK(I3),ISBLANK(J3)),"",_xlfn.TEXTBEFORE(F3,":")+_xlfn.TEXTBEFORE(G3,":")+_xlfn.TEXTBEFORE(H3,":")+_xlfn.TEXTBEFORE(I3,":")+_xlfn.TEXTBEFORE(J3,":")) -> 27.5 | M3: Need Mitigation
A4: 2 | B4: Client | C4: Insecure Communication | D4: Data exchanged between client and server can be intercepted or altered. | E4: Tampering | F4: 5: Information disclosure | G4: 7.5: Easy | H4: 2.5: Advanced programming and networking skills | I4: 10: All users | J4: 5: HTTP requests can uncover the vulnerability | K4: =IF(OR(ISBLANK(F4),ISBLANK(G4),ISBLANK(H4),ISBLANK(I4),ISBLANK(J4)),"",_xlfn.TEXTBEFORE(F4,":")+_xlfn.TEXTBEFORE(G4,":")+_xlfn.TEXTBEFORE(H4,":")+_xlfn.TEXTBEFORE(I4,":")+_xlfn.TEXTBEFORE(J4,":")) -> 30 | M4: Need Mitigation
A5: 3 | C5: Operational Errors | D5: Mismatch between client and server schemas causes system malfunctions. | E5: Denial of Service (DoS) | F5: 10: Destruction of an information system data or application unavailability | G5: 7.5: Easy | H5: 10: Web browser | I5: 10: All users | J5: 5: HTTP requests can uncover the vulnerability | K5: =IF(OR(ISBLANK(F5),ISBLANK(G5),ISBLANK(H5),ISBLANK(I5),ISBLANK(J5)),"",_xlfn.TEXTBEFORE(F5,":")+_xlfn.TEXTBEFORE(G5,":")+_xlfn.TEXTBEFORE(H5,":")+_xlfn.TEXTBEFORE(I5,":")+_xlfn.TEXTBEFORE(J5,":")) -> 42.5 | M5: Need Mitigation
A6: 4 | C6: Unpredictable Behavior | D6: Model instability results in irregular or disruptive requests. | E6: Denial of Service (DoS) | F6: 10: Destruction of an information system data or application unavailability | G6: 5: Complex | H6: 5: Available attack tools | I6: 10: All users | J6: 8: Vulnerability found in the public domain | K6: =IF(OR(ISBLANK(F6),ISBLANK(G6),ISBLANK(H6),ISBLANK(I6),ISBLANK(J6)),"",_xlfn.TEXTBEFORE(F6,":")+_xlfn.TEXTBEFORE(G6,":")+_xlfn.TEXTBEFORE(H6,":")+_xlfn.TEXTBEFORE(I6,":")+_xlfn.TEXTBEFORE(J6,":")) -> 38 | M6: Need Mitigation
A7: 5 | B7: Host | C7: AI Model Vulnerabilities | D7: Faulty outputs or exploited weaknesses disrupt MCP function. | E7: Denial of Service (DoS) | F7: 10: Destruction of an information system data or application unavailability | G7: 5: Complex | H7: 10: Web browser | I7: 6: Few users | J7: 5: HTTP requests can uncover the vulnerability | K7: =IF(OR(ISBLANK(F7),ISBLANK(G7),ISBLANK(H7),ISBLANK(I7),ISBLANK(J7)),"",_xlfn.TEXTBEFORE(F7,":")+_xlfn.TEXTBEFORE(G7,":")+_xlfn.TEXTBEFORE(H7,":")+_xlfn.TEXTBEFORE(I7,":")+_xlfn.TEXTBEFORE(J7,":")) -> 36 | M7: Need Mitigation
A8: 6 | C8: Host System Compromise | D8: Host machine compromise leads to unauthorized privilege escalation. | E8: Elevation of Privilege | F8: 8: Non-sensitive user data related to individuals or employer compromised | G8: 5: Complex | H8: 5: Available attack tools | I8: 2.5: Individual user | J8: 0: Hard to discover the vulnerability | K8: =IF(OR(ISBLANK(F8),ISBLANK(G8),ISBLANK(H8),ISBLANK(I8),ISBLANK(J8)),"",_xlfn.TEXTBEFORE(F8,":")+_xlfn.TEXTBEFORE(G8,":")+_xlfn.TEXTBEFORE(H8,":")+_xlfn.TEXTBEFORE(I8,":")+_xlfn.TEXTBEFORE(J8,":")) -> 20.5 | M8: Need Mitigation
A9: 7 | C9: Compromise and Unauthorized Access | D9: Misconfigurations or insecure setups allow intruder access. | E9: Spoofing | F9: 10: Destruction of an information system data or application unavailability | G9: 7.5: Easy | H9: 9: Web application proxies | I9: 10: All users | J9: 8: Vulnerability found in the public domain | K9: =IF(OR(ISBLANK(F9),ISBLANK(G9),ISBLANK(H9),ISBLANK(I9),ISBLANK(J9)),"",_xlfn.TEXTBEFORE(F9,":")+_xlfn.TEXTBEFORE(G9,":")+_xlfn.TEXTBEFORE(H9,":")+_xlfn.TEXTBEFORE(I9,":")+_xlfn.TEXTBEFORE(J9,":")) -> 44.5 | M9: Need Mitigation
A10: 8 | C10: Exploitation of Functions | D10: Attackers misuse tools to perform unintended or harmful operations | E10: Tampering | F10: 5: Information disclosure | G10: 5: Complex | H10: 9: Web application proxies | I10: 10: All users | J10: 8: Vulnerability found in the public domain | K10: =IF(OR(ISBLANK(F10),ISBLANK(G10),ISBLANK(H10),ISBLANK(I10),ISBLANK(J10)),"",_xlfn.TEXTBEFORE(F10,":")+_xlfn.TEXTBEFORE(G10,":")+_xlfn.TEXTBEFORE(H10,":")+_xlfn.TEXTBEFORE(I10,":")+_xlfn.TEXTBEFORE(J10,":")) -> 37 | M10: Need Mitigation
A11: 9 | C11: Denial of Service | D11: Overloading the server with excessive or looping requests disrupts service | E11: Denial of Service (DoS) | F11: 10: Destruction of an information system data or application unavailability | G11: 7.5: Easy | H11: 9: Web application proxies | I11: 10: All users | J11: 5: HTTP requests can uncover the vulnerability | K11: =IF(OR(ISBLANK(F11),ISBLANK(G11),ISBLANK(H11),ISBLANK(I11),ISBLANK(J11)),"",_xlfn.TEXTBEFORE(F11,":")+_xlfn.TEXTBEFORE(G11,":")+_xlfn.TEXTBEFORE(H11,":")+_xlfn.TEXTBEFORE(I11,":")+_xlfn.TEXTBEFORE(J11,":")) -> 41.5
A12: 10 | B12: MCP Server | C12: Vulnerable Communication | D12: Data transmitted between entities may be intercepted or modified. | E12: Tampering | F12: 9: Non-sensitive administrative data compromised | G12: 7.5: Easy | H12: 9: Web application proxies | I12: 10: All users | J12: 5: HTTP requests can uncover the vulnerability | K12: =IF(OR(ISBLANK(F12),ISBLANK(G12),ISBLANK(H12),ISBLANK(I12),ISBLANK(J12)),"",_xlfn.TEXTBEFORE(F12,":")+_xlfn.TEXTBEFORE(G12,":")+_xlfn.TEXTBEFORE(H12,":")+_xlfn.TEXTBEFORE(I12,":")+_xlfn.TEXTBEFORE(J12,":")) -> 40.5
A13: 11 | C13: Client Interference | D13: Lack of isolation allows one client’s activity to affect others. | E13: Denial of Service (DoS) | F13: 8: Non-sensitive user data related to individuals or employer compromised | G13: 5: Complex | H13: 5: Available attack tools | I13: 6: Few users | J13: 0: Hard to discover the vulnerability | K13: =IF(OR(ISBLANK(F13),ISBLANK(G13),ISBLANK(H13),ISBLANK(I13),ISBLANK(J13)),"",_xlfn.TEXTBEFORE(F13,":")+_xlfn.TEXTBEFORE(G13,":")+_xlfn.TEXTBEFORE(H13,":")+_xlfn.TEXTBEFORE(I13,":")+_xlfn.TEXTBEFORE(J13,":")) -> 24
A14: 12 | C14: Data Leakage and Compliance Violations | D14: Sensitive data is exfiltrated or mishandled, breaching regulations. | E14: Information Disclosure | F14: 8: Non-sensitive user data related to individuals or employer compromised | G14: 5: Complex | H14: 2.5: Advanced programming and networking skills | I14: 6: Few users | J14: 5: HTTP requests can uncover the vulnerability | K14: =IF(OR(ISBLANK(F14),ISBLANK(G14),ISBLANK(H14),ISBLANK(I14),ISBLANK(J14)),"",_xlfn.TEXTBEFORE(F14,":")+_xlfn.TEXTBEFORE(G14,":")+_xlfn.TEXTBEFORE(H14,":")+_xlfn.TEXTBEFORE(I14,":")+_xlfn.TEXTBEFORE(J14,":")) -> 26.5
A15: 13 | C15: Insufficient Auditability | D15: Weak or missing logs make security incident investigation difficult. | E15: Repudiation | F15: 5: Information disclosure | G15: 5: Complex | H15: 2.5: Advanced programming and networking skills | I15: 2.5: Individual user | J15: 0: Hard to discover the vulnerability | K15: =IF(OR(ISBLANK(F15),ISBLANK(G15),ISBLANK(H15),ISBLANK(I15),ISBLANK(J15)),"",_xlfn.TEXTBEFORE(F15,":")+_xlfn.TEXTBEFORE(G15,":")+_xlfn.TEXTBEFORE(H15,":")+_xlfn.TEXTBEFORE(I15,":")+_xlfn.TEXTBEFORE(J15,":")) -> 15
A16: 14 | C16: Server Spoofing | D16: Fake servers imitate legitimate ones to deceive users or systems. | E16: Spoofing | F16: 9: Non-sensitive administrative data compromised | G16: 5: Complex | H16: 2.5: Advanced programming and networking skills | I16: 10: All users | J16: 0: Hard to discover the vulnerability | K16: =IF(OR(ISBLANK(F16),ISBLANK(G16),ISBLANK(H16),ISBLANK(I16),ISBLANK(J16)),"",_xlfn.TEXTBEFORE(F16,":")+_xlfn.TEXTBEFORE(G16,":")+_xlfn.TEXTBEFORE(H16,":")+_xlfn.TEXTBEFORE(I16,":")+_xlfn.TEXTBEFORE(J16,":")) -> 26.5
A17: 15 | C17: Data - Insufficient Access Control | D17: Weak data protection permits unauthorized access. | E17: Information Disclosure | F17: 10: Destruction of an information system data or application unavailability | G17: 0: Difficult or impossible | H17: 5: Available attack tools | I17: 10: All users | J17: 0: Hard to discover the vulnerability | K17: =IF(OR(ISBLANK(F17),ISBLANK(G17),ISBLANK(H17),ISBLANK(I17),ISBLANK(J17)),"",_xlfn.TEXTBEFORE(F17,":")+_xlfn.TEXTBEFORE(G17,":")+_xlfn.TEXTBEFORE(H17,":")+_xlfn.TEXTBEFORE(I17,":")+_xlfn.TEXTBEFORE(J17,":")) -> 25
A18: 16 | C18: Data Integrity Issues | D18: Altered or inconsistent data leads to incorrect outcomes. | E18: Tampering | F18: 10: Destruction of an information system data or application unavailability | G18: 5: Complex | H18: 2.5: Advanced programming and networking skills | I18: 10: All users | J18: 0: Hard to discover the vulnerability | K18: =IF(OR(ISBLANK(F18),ISBLANK(G18),ISBLANK(H18),ISBLANK(I18),ISBLANK(J18)),"",_xlfn.TEXTBEFORE(F18,":")+_xlfn.TEXTBEFORE(G18,":")+_xlfn.TEXTBEFORE(H18,":")+_xlfn.TEXTBEFORE(I18,":")+_xlfn.TEXTBEFORE(J18,":")) -> 27.5
A19: 17 | B19: Database, tools, API | C19: Data Exfiltration | D19: Confidential data is extracted without authorization. | E19: Information Disclosure | F19: 9: Non-sensitive administrative data compromised | G19: 0: Difficult or impossible | H19: 2.5: Advanced programming and networking skills | I19: 10: All users | J19: 0: Hard to discover the vulnerability | K19: =IF(OR(ISBLANK(F19),ISBLANK(G19),ISBLANK(H19),ISBLANK(I19),ISBLANK(J19)),"",_xlfn.TEXTBEFORE(F19,":")+_xlfn.TEXTBEFORE(G19,":")+_xlfn.TEXTBEFORE(H19,":")+_xlfn.TEXTBEFORE(I19,":")+_xlfn.TEXTBEFORE(J19,":")) -> 21.5
A20: 18 | C20: Tool - Functional Misuse | D20: Tools are used beyond their intended security scope. | E20: Tampering | F20: 8: Non-sensitive user data related to individuals or employer compromised | G20: 5: Complex | H20: 2.5: Advanced programming and networking skills | I20: 10: All users | J20: 5: HTTP requests can uncover the vulnerability | K20: =IF(OR(ISBLANK(F20),ISBLANK(G20),ISBLANK(H20),ISBLANK(I20),ISBLANK(J20)),"",_xlfn.TEXTBEFORE(F20,":")+_xlfn.TEXTBEFORE(G20,":")+_xlfn.TEXTBEFORE(H20,":")+_xlfn.TEXTBEFORE(I20,":")+_xlfn.TEXTBEFORE(J20,":")) -> 30.5
A21: 19 | C21: Tool - Resource Exhaustion | D21: Excessive tool use depletes available resources. | E21: Denial of Service (DoS) | F21: 10: Destruction of an information system data or application unavailability | G21: 7.5: Easy | H21: 5: Available attack tools | I21: 10: All users | J21: 5: HTTP requests can uncover the vulnerability | K21: =IF(OR(ISBLANK(F21),ISBLANK(G21),ISBLANK(H21),ISBLANK(I21),ISBLANK(J21)),"",_xlfn.TEXTBEFORE(F21,":")+_xlfn.TEXTBEFORE(G21,":")+_xlfn.TEXTBEFORE(H21,":")+_xlfn.TEXTBEFORE(I21,":")+_xlfn.TEXTBEFORE(J21,":")) -> 37.5
A22: 20 | C22: Tool - Tool Poisoning | D22: Malicious modifications corrupt tool metadata or functionality. | E22: Tampering | F22: 9: Non-sensitive administrative data compromised | G22: 7.5: Easy | H22: 2.5: Advanced programming and networking skills | I22: 10: All users | J22: 0: Hard to discover the vulnerability | K22: =IF(OR(ISBLANK(F22),ISBLANK(G22),ISBLANK(H22),ISBLANK(I22),ISBLANK(J22)),"",_xlfn.TEXTBEFORE(F22,":")+_xlfn.TEXTBEFORE(G22,":")+_xlfn.TEXTBEFORE(H22,":")+_xlfn.TEXTBEFORE(I22,":")+_xlfn.TEXTBEFORE(J22,":")) -> 29
A23: 21 | C23: Prompt Injection | D23: Malicious prompts manipulate model behavior or leak data. | E23: Tampering | F23: 10: Destruction of an information system data or application unavailability | G23: 7.5: Easy | H23: 10: Web browser | I23: 10: All users | J23: 10: Vulnerability found in web address bar or form | K23: =IF(OR(ISBLANK(F23),ISBLANK(G23),ISBLANK(H23),ISBLANK(I23),ISBLANK(J23)),"",_xlfn.TEXTBEFORE(F23,":")+_xlfn.TEXTBEFORE(G23,":")+_xlfn.TEXTBEFORE(H23,":")+_xlfn.TEXTBEFORE(I23,":")+_xlfn.TEXTBEFORE(J23,":")) -> 47.5
A24: 22 | C24: Insecure Output Handling | D24: Poor validation of model responses exposes sensitive data or executes unintended actions. | E24: Information Disclosure | F24: 8: Non-sensitive user data related to individuals or employer compromised | G24: 7.5: Easy | H24: 10: Web browser | I24: 10: All users | J24: 10: Vulnerability found in web address bar or form | K24: =IF(OR(ISBLANK(F24),ISBLANK(G24),ISBLANK(H24),ISBLANK(I24),ISBLANK(J24)),"",_xlfn.TEXTBEFORE(F24,":")+_xlfn.TEXTBEFORE(G24,":")+_xlfn.TEXTBEFORE(H24,":")+_xlfn.TEXTBEFORE(I24,":")+_xlfn.TEXTBEFORE(J24,":")) -> 45.5
A25: 23 | C25: Training Data Poisoning | D25: Tampered training data reduces model accuracy or integrity. | E25: Tampering | F25: 5: Information disclosure | G25: 7.5: Easy | H25: 2.5: Advanced programming and networking skills | I25: 10: All users | J25: 0: Hard to discover the vulnerability | K25: =IF(OR(ISBLANK(F25),ISBLANK(G25),ISBLANK(H25),ISBLANK(I25),ISBLANK(J25)),"",_xlfn.TEXTBEFORE(F25,":")+_xlfn.TEXTBEFORE(G25,":")+_xlfn.TEXTBEFORE(H25,":")+_xlfn.TEXTBEFORE(I25,":")+_xlfn.TEXTBEFORE(J25,":")) -> 25
A26: 24 | C26: Model Denial of Service | D26: Resource-intensive prompts disrupt normal model operation. | E26: Denial of Service (DoS) | F26: 10: Destruction of an information system data or application unavailability | G26: 5: Complex | H26: 5: Available attack tools | I26: 10: All users | J26: 5: HTTP requests can uncover the vulnerability | K26: =IF(OR(ISBLANK(F26),ISBLANK(G26),ISBLANK(H26),ISBLANK(I26),ISBLANK(J26)),"",_xlfn.TEXTBEFORE(F26,":")+_xlfn.TEXTBEFORE(G26,":")+_xlfn.TEXTBEFORE(H26,":")+_xlfn.TEXTBEFORE(I26,":")+_xlfn.TEXTBEFORE(J26,":")) -> 35
A27: 25 | B27: LLM | C27: Supply Chain Vulnerabilities | D27: Compromised datasets or dependencies reduce trustworthiness. | E27: Tampering | F27: 8: Non-sensitive user data related to individuals or employer compromised | G27: 5: Complex | H27: 2.5: Advanced programming and networking skills | I27: 10: All users | J27: 0: Hard to discover the vulnerability | K27: =IF(OR(ISBLANK(F27),ISBLANK(G27),ISBLANK(H27),ISBLANK(I27),ISBLANK(J27)),"",_xlfn.TEXTBEFORE(F27,":")+_xlfn.TEXTBEFORE(G27,":")+_xlfn.TEXTBEFORE(H27,":")+_xlfn.TEXTBEFORE(I27,":")+_xlfn.TEXTBEFORE(J27,":")) -> 25.5
A28: 26 | C28: Sensitive Information Disclosure | D28: Model outputs unintentionally reveal confidential information. | E28: Information Disclosure | F28: 8: Non-sensitive user data related to individuals or employer compromised | G28: 5: Complex | H28: 2.5: Advanced programming and networking skills | I28: 10: All users | J28: 5: HTTP requests can uncover the vulnerability | K28: =IF(OR(ISBLANK(F28),ISBLANK(G28),ISBLANK(H28),ISBLANK(I28),ISBLANK(J28)),"",_xlfn.TEXTBEFORE(F28,":")+_xlfn.TEXTBEFORE(G28,":")+_xlfn.TEXTBEFORE(H28,":")+_xlfn.TEXTBEFORE(I28,":")+_xlfn.TEXTBEFORE(J28,":")) -> 30.5
A29: 27 | C29: Insecure Plugin Design | D29: Poor plugin controls enable unauthorized system actions. | E29: Elevation of Privilege | F29: 10: Destruction of an information system data or application unavailability | G29: 5: Complex | H29: 2.5: Advanced programming and networking skills | I29: 10: All users | J29: 0: Hard to discover the vulnerability | K29: =IF(OR(ISBLANK(F29),ISBLANK(G29),ISBLANK(H29),ISBLANK(I29),ISBLANK(J29)),"",_xlfn.TEXTBEFORE(F29,":")+_xlfn.TEXTBEFORE(G29,":")+_xlfn.TEXTBEFORE(H29,":")+_xlfn.TEXTBEFORE(I29,":")+_xlfn.TEXTBEFORE(J29,":")) -> 27.5
A30: 28 | C30: Excessive Agency | D30: Overly autonomous models make unsafe or unauthorized decisions | E30: Elevation of Privilege | F30: 10: Destruction of an information system data or application unavailability | G30: 5: Complex | H30: 2.5: Advanced programming and networking skills | I30: 10: All users | J30: 5: HTTP requests can uncover the vulnerability | K30: =IF(OR(ISBLANK(F30),ISBLANK(G30),ISBLANK(H30),ISBLANK(I30),ISBLANK(J30)),"",_xlfn.TEXTBEFORE(F30,":")+_xlfn.TEXTBEFORE(G30,":")+_xlfn.TEXTBEFORE(H30,":")+_xlfn.TEXTBEFORE(I30,":")+_xlfn.TEXTBEFORE(J30,":")) -> 32.5
A31: 29 | C31: Overreliance | D31: Blind trust in model outputs leads to security or decision errors. | E31: Tampering | F31: 8: Non-sensitive user data related to individuals or employer compromised | G31: 7.5: Easy | H31: 9: Web application proxies | I31: 10: All users | J31: 0: Hard to discover the vulnerability | K31: =IF(OR(ISBLANK(F31),ISBLANK(G31),ISBLANK(H31),ISBLANK(I31),ISBLANK(J31)),"",_xlfn.TEXTBEFORE(F31,":")+_xlfn.TEXTBEFORE(G31,":")+_xlfn.TEXTBEFORE(H31,":")+_xlfn.TEXTBEFORE(I31,":")+_xlfn.TEXTBEFORE(J31,":")) -> 34.5
A32: 30 | C32: Model Theft | D32: Unauthorized access to model parameters or structure exposes proprietary assets. | E32: Information Disclosure | F32: 8: Non-sensitive user data related to individuals or employer compromised | G32: 5: Complex | H32: 2.5: Advanced programming and networking skills | I32: 10: All users | J32: 0: Hard to discover the vulnerability | K32: =IF(OR(ISBLANK(F32),ISBLANK(G32),ISBLANK(H32),ISBLANK(I32),ISBLANK(J32)),"",_xlfn.TEXTBEFORE(F32,":")+_xlfn.TEXTBEFORE(G32,":")+_xlfn.TEXTBEFORE(H32,":")+_xlfn.TEXTBEFORE(I32,":")+_xlfn.TEXTBEFORE(J32,":")) -> 25.5
A33: 31 | C33: Eavesdropping Access Tokens | D33: Tokens intercepted during transmission are reused by attackers. | E33: Information Disclosure | F33: 8: Non-sensitive user data related to individuals or employer compromised | G33: 5: Complex | H33: 9: Web application proxies | I33: 6: Few users | J33: 5: HTTP requests can uncover the vulnerability | K33: =IF(OR(ISBLANK(F33),ISBLANK(G33),ISBLANK(H33),ISBLANK(I33),ISBLANK(J33)),"",_xlfn.TEXTBEFORE(F33,":")+_xlfn.TEXTBEFORE(G33,":")+_xlfn.TEXTBEFORE(H33,":")+_xlfn.TEXTBEFORE(I33,":")+_xlfn.TEXTBEFORE(J33,":")) -> 33
A34: 32 | B34: Authorization Server | C34: Obtaining Access Tokens from Authorization Server Database | D34: Attackers exploit database vulnerabilities to retrieve tokens by gaining access to the database or launching a SQL injection attack. | E34: Information Disclosure | F34: 9: Non-sensitive administrative data compromised | G34: 5: Complex | H34: 5: Available attack tools | I34: 10: All users | J34: 0: Hard to discover the vulnerability | K34: =IF(OR(ISBLANK(F34),ISBLANK(G34),ISBLANK(H34),ISBLANK(I34),ISBLANK(J34)),"",_xlfn.TEXTBEFORE(F34,":")+_xlfn.TEXTBEFORE(G34,":")+_xlfn.TEXTBEFORE(H34,":")+_xlfn.TEXTBEFORE(I34,":")+_xlfn.TEXTBEFORE(J34,":")) -> 29
A35: 33 | C35: Disclosure of Client Credentials during Transmission | D35: Login credentials are intercepted during the client authentication process or during OAuth token requests. | E35: Information Disclosure | F35: 8: Non-sensitive user data related to individuals or employer compromised | G35: 5: Complex | H35: 9: Web application proxies | I35: 10: All users | J35: 5: HTTP requests can uncover the vulnerability | K35: =IF(OR(ISBLANK(F35),ISBLANK(G35),ISBLANK(H35),ISBLANK(I35),ISBLANK(J35)),"",_xlfn.TEXTBEFORE(F35,":")+_xlfn.TEXTBEFORE(G35,":")+_xlfn.TEXTBEFORE(H35,":")+_xlfn.TEXTBEFORE(I35,":")+_xlfn.TEXTBEFORE(J35,":")) -> 37
A36: 34 | C36: Obtaining Client Secret from Authorization Server Database | D36: Valid client credentials are extracted from stored data | E36: Information Disclosure | F36: 8: Non-sensitive user data related to individuals or employer compromised | G36: 5: Complex | H36: 2.5: Advanced programming and networking skills | I36: 6: Few users | J36: 0: Hard to discover the vulnerability | K36: =IF(OR(ISBLANK(F36),ISBLANK(G36),ISBLANK(H36),ISBLANK(I36),ISBLANK(J36)),"",_xlfn.TEXTBEFORE(F36,":")+_xlfn.TEXTBEFORE(G36,":")+_xlfn.TEXTBEFORE(H36,":")+_xlfn.TEXTBEFORE(I36,":")+_xlfn.TEXTBEFORE(J36,":")) -> 21.5
A37: 35 | C37: Obtaining Client Secret by Online Guessing | D37: Attackers attempt to brute-force valid client ID/secret pairs | E37: Spoofing | F37: 8: Non-sensitive user data related to individuals or employer compromised | G37: 0: Difficult or impossible | H37: 2.5: Advanced programming and networking skills | I37: 6: Few users | J37: 0: Hard to discover the vulnerability | K37: =IF(OR(ISBLANK(F37),ISBLANK(G37),ISBLANK(H37),ISBLANK(I37),ISBLANK(J37)),"",_xlfn.TEXTBEFORE(F37,":")+_xlfn.TEXTBEFORE(G37,":")+_xlfn.TEXTBEFORE(H37,":")+_xlfn.TEXTBEFORE(I37,":")+_xlfn.TEXTBEFORE(J37,":")) -> 16.5
K38: =IF(OR(ISBLANK(F38),ISBLANK(G38),ISBLANK(H38),ISBLANK(I38),ISBLANK(J38)),"",_xlfn.TEXTBEFORE(F38,":")+_xlfn.TEXTBEFORE(G38,":")+_xlfn.TEXTBEFORE(H38,":")+_xlfn.TEXTBEFORE(I38,":")+_xlfn.TEXTBEFORE(J38,":"))
K39: =IF(OR(ISBLANK(F39),ISBLANK(G39),ISBLANK(H39),ISBLANK(I39),ISBLANK(J39)),"",_xlfn.TEXTBEFORE(F39,":")+_xlfn.TEXTBEFORE(G39,":")+_xlfn.TEXTBEFORE(H39,":")+_xlfn.TEXTBEFORE(I39,":")+_xlfn.TEXTBEFORE(J39,":"))
K40: =IF(OR(ISBLANK(F40),ISBLANK(G40),ISBLANK(H40),ISBLANK(I40),ISBLANK(J40)),"",_xlfn.TEXTBEFORE(F40,":")+_xlfn.TEXTBEFORE(G40,":")+_xlfn.TEXTBEFORE(H40,":")+_xlfn.TEXTBEFORE(I40,":")+_xlfn.TEXTBEFORE(J40,":"))
...

Sheet STRIDE Description
D4: Type | E4: Description | F4: Security Control | G4: Mitigation Techniques
D5: Spoofing | E5: Threat action aimed at accessing and use of another user’s credentials, such as username and password. | F5: Authentication | G5: 1. Appropriate authentication 2. Protect secret data 3. Don’t store secrets
D6: Tampering | E6: Threat action intending to maliciously change or modify persistent data, such as records in a database, and the alteration of data in transit between two computers over an open network, such as the Internet. | F6: Integrity | G6: 1. Appropriate authorization 2. Hashes 3. MACs 4. Digital signatures 5. Tamper resistant protocols
D7: Repudiation | E7: Threat action aimed at performing prohibited operations in a system that lacks the ability to trace the operations. | F7: Non-Repudiation | G7: 1. Digital signatures 2. Timestamps 3. Audit trails
D8: Information disclosure | E8: Threat action intending to read a file that one was not granted access to, or to read data in transit. | F8: Confidentiality | G8: 1. Authorization 2. Privacy-enhanced protocols 3. Encryption 4. Protect secrets 5. Don’t store secrets
D9: Denial of service | E9: Threat action attempting to deny access to valid users, such as by making a web server temporarily unavailable or unusable. | F9: Availability | G9: 1. Appropriate authentication 2. Appropriate authorization 3. Filtering 4. Throttling 5. Quality of service
D10: Elevation of privilege | E10: Threat action intending to gain privileged access to resources in order to gain unauthorized access to information or to compromise a system. | F10: Authorization | G10: 1. Run with least privilege
